Workbook
Name ATC: ATC!$A$2:$A$593
Name CIRUGIA: 'CUPS CIRUGÍA'!$A$9
Name CUPSCX: 'CUPS CIRUGÍA'!$A$2:$A$2557
Name IPS: CÓD_HABILITACIÓN!$A$2:$A$111

Sheet PACIENTES
A1: No. VARIABLE | B1: 1 | C1: 2 | D1: 3 | E1: 4 | F1: 5 | G1: 6 | H1: 7 | I1: 8 | J1: 9 | K1: 10 | L1: 11 | M1: 12 | N1: 13 | O1: 14 | P1: 15 | Q1: 16 | R1: 17 | S1: 18 | T1: 19 | U1: 20 | V1: 21 | W1: 22 | X1: 23 | Y1: 24 | Z1: 25 | AA1: 26 | AB1: 27 | AC1: 28 | AD1: 29 | AE1: 30 | AF1: 31 | AG1: 32 | AH1: 33 | AI1: 34 | AJ1: 35 | AK1: 36 | AL1: 37 | AM1: 38 | AN1: 39 | AO1: 40 | AP1: 41 | AQ1: 42 | AR1: 43 | AS1: 44 | AT1: 45 | AU1: 46 | AV1: 46.1 | AW1: 46.2 | AX1: 46.3 | AY1: 46.4 | AZ1: 46.5 | BA1: 46.6 | BB1: 46.7 | BC1: 46.8 | BD1: 47 | BE1: 48 | BF1: 49 | BG1: 50 | BH1: 51 | BI1: 52 | BJ1: 53 | BK1: 53.1 | BL1: 53.2 | BM1: 53.3 | BN1: 53.4 | BO1: 53.5 | BP1: 53.6 | BQ1: 53.7 | BR1: 53.8 | BS1: 53.9 | BT1: 54 | BU1: 55 | BV1: 56 | BW1: 57 | BX1: 58 | BY1: 59 | BZ1: 60 | CA1: 61 | CB1: 62 | CC1: 63 | CD1: 64 | CE1: 65 | CF1: 66 | CG1: 66.1 | CH1: 66.2 | CI1: 66.3 | CJ1: 66.4 | CK1: 66.5 | CL1: 66.6 | CM1: 66.7 | CN1: 66.8 | CO1: 66.9 | CP1: 67 | CQ1: 68 | CR1: 69 | CS1: 70 | CT1: 71 | CU1: 72 | CV1: 73 | CW1: 74 | CX1: 75 | CY1: 76 | CZ1: 77 | DA1: 78 | DB1: 79 | DC1: 80 | DD1: 81 | DE1: 82 | DF1: 83 | DG1: 84 | DH1: 85 | DI1: 86 | DJ1: 87 | DK1: 88 | DL1: 89 | DM1: 90 | DN1: 91 | DO1: 92 | DP1: 93 | DQ1: 94 | DR1: 95 | DS1: 96 | DT1: 97 | DU1: 98 | DV1: 99 | DW1: 100 | DX1: 101 | DY1: 102 | DZ1: 103 | EA1: 104 | EB1: 105 | EC1: 106 | ED1: 107 | EE1: 108 | EF1: 109 | EG1: 110 | EH1: 111 | EI1: 112 | EJ1: 113 | EK1: 114 | EL1: 114.1 | EM1: 114.2 | EN1: 114.3 | EO1: 114.4 | EP1: 114.5 | EQ1: 114.6 | ER1: 115 | ES1: 116 | ET1: 117 | EU1: 118 | EV1: 119 | EW1: 120 | EX1: 121 | EY1: 122 | EZ1: 123 | FA1: 124 | FB1: 125 | FC1: 126 | FD1: 127 | FE1: 128 | FF1: 129 | FG1: 130 | FH1: 131 | FI1: 132 | FJ1: 133 | FK1: 134
A2: Nombre del campo | B2: Primer nombre del usuario | C2: Segundo nombre del usuario | D2: Primer apellido del usuario | E2: Segundo apellido del usuario | F2: Tipo de Identificación del usuario | G2: Número de Identificación del usuario | H2: Fecha de nacimiento | I2: Sexo | J2: Ocupación | K2: Régimen de afiliación AL SGSSS | L2: Código de la EPS o de la entidad territorial | M2: Código pertenencia étnica | N2: Grupo poblacional | O2: Municipio de residencia | P2: Númerotelefónicodelpaciente(incluyendoafamiliaresycuidadores) | Q2: Fecha de afiliación a la EAPB que reporta | R2: Codigo CIE -10 de la neoplasia (cáncer o tumor) maligna reportada(Primario) | S2: Fecha de Diagnóstico del Cáncer reportado | T2: Fecha de la nota de remisión del médico o institución general hacia la institución o médico que hizo el diagnóstico | U2: Fecha de ingreso a la institución que realizó el diagnóstico luego de la remisión intenconsulta | V2: Tipo de estudio con el que se realizó el diagnóstico de cáncer | W2: Motivo por el cual el usuario no tuvo diagnóstico por histopatología (aplica para registros con respuesta igual a 7 en la variable anterior) | X2: Fecha de recolección de muestra para estudio histopatológico de diagnóstico | Y2: Fecha de Primero o único informe histopatológico válido de diagnóstico | Z2: Código válido de habilitación de la IPS donde se realiza la confirmación diagnóstica | AA2: Fecha de primera consulta con médico tratante de la enfermedad maligna(médico especialista que define la primera conducta terapéutica-terapia sistémica, cirugía , radioterapia o cuidado paliativos- manejo expectante) | AB2: Histología del tumor en muestra de biopsia o quirúrgica | AC2: Grado de diferenciación del tumor sólido maligno según la biopsia o informe de primera cirugía | AD2: Si es tumor sólido, cuál fue la primera estadificación basada en TNM, FIGO, u otras compatibles con esta numeración según tumor. | AE2: Fecha en que se realizó esta estadificación | AF2: Para cáncer de mama, ¿se le realizó a este usuario la prueba HER2 (llamado también receptor 2 del factor de crecimiento epidérmico humano, también llamado erb-B2) antes del inicio del tratamiento? | AG2: Para cáncer de mama, fecha de realización de la última prueba HER2 | AH2: Para cáncer de mama, resultado de la ultima prueba HER2 | AI2: Para cáncer colorrectal, estadificación de Dukes | AJ2: Fecha en que se realizó la estadificación de Dukes | AK2: Estadificación clínica en linfoma no Hodgkin, linfoma Hodgkin adulto y pediátrico (Ann Arbor - Lugano) y mieloma múltiple | AL2: Para cáncer de próstata, valor de clasificación de la escala Gleason en el momento del diagnóstico | AM2: Clasificación de riesgo leucemias o linfomas, y sólidos pediátricos | AN2: Fecha de clasificación de riesgo | AO2: Objetivo (o intención) del tratamiento médico inicial (al diagnóstico) | AP2: Objetivo de la intervención médica durante el periodo de reporte. | AQ2: Tiene antecedente de otro cáncer primario (es decir, tiene o tuvo otro tumor maligno diferente al que está notificando) | AR2: Fecha de diagnóstico del otro cáncer primario | AS2: Tipo (CIE-10) de ese cáncer antecedente | AT2: ¿Recibió el usuario quimioterapia u otra terapia sistémica (incluye quimioterapia, hormonoterapia, inmunoterapia) dentro del periodo de corte actual? (Aclaración: en esta sección solo incluya ciclos iniciados en este corte. Por favor, no incluya el último ciclo informado como "actual" en el corte anterior, así se haya terminado en el periodo actual de reporte). | AU2: ¿Cuántas fases de quimioterapia recibió el usuario en este corte? (aplica para hematolinfáticos) | AV2: El usuario recibió en este corte la fase de quimioterapia denominada Prefase o Citorreducción inicial (aplica solo para leucemia linfoide aguda y linfoma linfoblástico, puede haber recibido más de una fase): | AW2: El usuario recibió en este corte la fase de quimioterapia denominada Inducción (aplica solo para leucemia linfoide o mieloide aguda y linfoma linfoblástico, puede haber recibido más de una fase) | AX2: El usuario recibió en este corte la fase de quimioterapia denominada Intensificación (aplica solo para leucemia linfoide aguda y o mieloide linfoma linfoblástico, puede haber recibido más de una fase) | AY2: El usuario recibió en este corte la fase de quimioterapia denominada Consolidación (aplica solo para leucemia linfoide aguda y o mieloide linfoma linfoblástico, puede haber recibido más de una fase) | AZ2: El usuario recibió en este corte la fase de quimioterapia denominada Reinducción (aplica solo para leucemia linfoide aguda y linfoma linfoblástico, puede haber recibido más de una fase | BA2: El usuario recibió en este corte la fase de quimioterapia denominada Mantenimiento (aplica solo para leucemia linfoide o mieloide aguda y linfoma linfoblástico, puede haber recibido más de una fase) | BB2: El usuario recibió en este corte la fase de quimioterapia denominada Mantenimiento largo o final (aplica solo para leucemia linfoide o mieloide aguda y linfoma linfoblástico, puede haber recibido más de una fase) | BC2: El usuario recibió en este corte Otra fase de quimioterapia denominada diferente a las anteriores (aplica solo para leucemia linfoide o mieloide aguda y linfoma linfoblástico, puede haber recibido más de una fase) | BD2: Número de ciclos iniciados y administrados en el periodo de reporte, incluyendo el que aún recibe en la fecha de corte. | BE2: Ubicación temporal del primer ciclo en el periodo en relación al manejo oncológico | BF2: Fecha de inicio del primer ESQUEMA de quimioterapia de este periodo de reporte. Si es hormonoterapia reporte la fecha de inicio del tratamiento actual, así haya sido iniciada previo al reporte actual | BG2: Número de IPS que suministran el primer ciclo de este corte | BH2: Código de la IPS1 que suministra el primer ciclo de este corte | BI2: Código de la IPS2 que suministra el primer ciclo de este corte | BJ2: Cuantos medicamentos antineoplásicos, el (los) especialista(s) tratante(s) del cáncer propusieron como manejo en el primer ciclo de este corte | BK2: Medicamento antineoplasico administrado al usuario - PRIMER O UNICO esquema en el periodo del reporte | BL2: Medicamento antineoplasico administrado al usuario - PRIMER O UNICO esquema en el periodo del reporte | BM2: Medicamento antineoplasico administrado al usuario - PRIMER O UNICO esquema en el periodo del reporte | BN2: Medicamento antineoplasico administrado al usuario - PRIMER O UNICO esquema en el periodo del reporte | BO2: Medicamento antineoplasico administrado al usuario - PRIMER O UNICO esquema en el periodo del reporte | BP2: Medicamento antineoplasico administrado al usuario - PRIMER O UNICO esquema en el periodo del reporte | BQ2: Medicamento antineoplasico administrado al usuario - PRIMER O UNICO esquema en el periodo del reporte | BR2: Medicamento antineoplasico administrado al usuario - PRIMER O UNICO esquema en el periodo del reporte | BS2: Medicamento antineoplasico administrado al usuario - PRIMER O UNICO esquema en el periodo del reporte | BT2: Medicamento ANTINEOPLASICO - o terapia hormonal para cancer, adicional a los reportados en las variables 53.1 a 53.9, administrados al usuario en el primer o unico esquema. | BU2: Medicamento ANTINEOPLASICO - o terapia hormonal para cancer, adicional a los reportados en las variables 53.1 a 53.9, administrados al usuario en el primer o unico esquema. | BV2: Medicamento ANTINEOPLASICO - o terapia hormonal para cancer, adicional a los reportados en las variables 53.1 a 53.9, administrados al usuario en el primer o unico esquema. | BW2: ¿Recibió quimioterapia intratecal en el primer ciclo de este corte? | BX2: Fecha de finalización del primer ESQUEMA de este periodo de reporte. Si es hormonoterapia reporte la fecha de finalización del tratamiento actual | BY2: Características actuales del primer ESQUEMA de este corte | BZ2: Motivo de la finalización (prematura) de este primer ESQUEMA (Aplica si registró la opción 2 de la pregunta anterior) Selecciona un sólo número (lo que primero ocurrió). | CA2: Ubicación temporal del último ESQUEMA de este corte en relación al manejo oncológico | CB2: Fecha de inicio del últimoESQUEMA de quimioterapia de este periodo de reporte. Si es hormonoterapia reporte la fecha de inicio del tratamiento actual, así haya sido iniciada previo al reporte actual | CC2: Número de IPS que suministran el último ESQUEMA de este corte | CD2: Código de la IPS1 que suministra el último ESQUEMA en este reporte | CE2: Código de la IPS2 que suministra el último ESQUEMA en este reporte | CF2: Cuantos medicamentos antineoplásicos, el (los) especialista(s) tratante(s) del cáncer propusieron como manejo en este último ciclo de este corte | CG2: Medicamento antineoplasico administrado al usuario - ULTIMO esquema en el periodo del reporte | CH2: Medicamento antineoplasico administrado al usuario - ULTIMO esquema en el periodo del reporte | CI2: Medicamento antineoplasico administrado al usuario - ULTIMO esquema en el periodo del reporte | CJ2: Medicamento antineoplasico administrado al usuario - ULTIMO esquema en el periodo del reporte | CK2: Medicamento antineoplasico administrado al usuario - ULTIMO esquema en el periodo del reporte | CL2: Medicamento antineoplasico administrado al usuario - ULTIMO esquema en el periodo del reporte | CM2: Medicamento antineoplasico administrado al usuario - ULTIMO esquema en el periodo del reporte | CN2: Medicamento antineoplasico administrado al usuario - ULTIMO esquema en el periodo del reporte | CO2: Medicamento antineoplasico administrado al usuario - ULTIMO esquema en el periodo del reporte | CP2: Medicamento ANTINEOPLASICO - o terapia hormonal para cancer, adicional a los reportados en las variables 66.1 a 66.9, administrados al usuario en el ultimo esquema | CQ2: Medicamento ANTINEOPLASICO - o terapia hormonal para cancer, adicional a los reportados en las variables 66.1 a 66.9, administrados al usuario en el ultimo esquema | CR2: Medicamento ANTINEOPLASICO - o terapia hormonal para cancer, adicional a los reportados en las variables 66.1 a 66.9, administrados al usuario en el ultimo esquema | CS2: ¿Recibió quimioterapia intratecal en el último ciclo de este corte? | CT2: Fecha de finalización del último ESQUEMA de este periodo de reporte. Si es hormonoterapia reporte la fecha de finalización del tratamiento actual | CU2: Características actuales del último ESQUEMA de este corte | CV2: Motivo de la finalización (prematura) de este último ciclo (Aplica si registró la opción 2 de la pregunta anterior) Selecciona un sólo número (lo que primero ocurrió). | CW2: ¿Fue sometido el usuario a una o más cirugías curativas o paliativas como parte del manejo del cáncer durante este reporte? | CX2: Número de cirugías a las que fue sometido el usuario durante el periodo de reporte actual | CY2: Fecha de realización de la primera cirugía en este reporte | CZ2: Código de la IPS que realizó la primera cirugía de este corte | DA2: Código de primera cirugía | DB2: Ubicación temporal de esta primera cirugía en relación al manejo oncológico | DC2: Fecha de realización del último procedimiento quirúrgico o de reintervención en este corte. | DD2: Motivo de haber realizado la última intervención quirúrgica de este este periodo de reporte | DE2: Código de la IPS que realiza el último de los procedimientos quirúrgicos en este corte | DF2: Código de última cirugía | DG2: Ubicación temporal de esta última cirugía en relación al manejo oncológico, en este periodo de reporte | DH2: Estado vital al finalizar la única o última cirugía de este periodo de reporte | DI2: ¿Recibió el usuario algún tipo de radioterapia en el corte actual? | DJ2: Número de sesiones de radioterapia suministrados en el periodo de reporte actual | DK2: Fecha de inicio de primer o único esquema de radioterapia suministrado en el corte actual | DL2: Ubicación temporal del primer o único esquema de radioterapia en este corte | DM2: Tipo de radioterapia aplicada en este primer o único esquema | DN2: Número de IPS que suministran este primer o único esquema de radioterapia | DO2: Código de la IPS1 que suministra la radioterapia | DP2: Código de la IPS2 que suministra la radioterapia | DQ2: Fecha de finalización de primer o único esquema de radioterapia | DR2: Características actuales de este primer o único esquema de radioterapia | DS2: Motivo de la finalización de este primer o único esquema de radioterapia (Aplica si registró la opción 2 de la pregunta anterior) Selecciona un sólo número (lo que primero ocurrió). | DT2: Fecha de inicio del último esquema de radioterapia suministrado en el corte actual | DU2: Ubicación temporal/Intención del último esquema de radioterapia suministrado en el corte actual | DV2: Tipo de radioterapia aplicada en el último esquema de radioterapia suministrado en el corte actual | DW2: Número de IPS que suministran este último esquema de radioterapia suministrado en el corte actual | DX2: Código de la IPS1 que suministra la radioterapia | DY2: Código de la IPS2 que suministra la radioterapia | DZ2: Fecha de finalización del último esquema de radioterapia suministrado en el corte actual | EA2: Características actuales de este último esquema de radioterapia suministrado en el corte actual | EB2: Motivo de la finalización de este último esquema de radioterapia suministrado en el corte actual (Aplica si registró la opción 2 de la pregunta anterior) Selecciona un sólo número (lo que primero ocurrió). | EC2: ¿Recibió el usuario trasplante de células progenitoras hematopoyética dentro del periodo de corte actual? | ED2: Tipo de trasplante recibido | EE2: Ubicación temporal de este trasplante en relación al manejo oncológico | EF2: Fecha de trasplante | EG2: Código de la IPS que realizó este trasplante | EH2: El usuario, ¿recibió cirugía reconstructiva? | EI2: Fecha de la cirugía | EJ2: Código de la IPS que realizó cirugía reconstructiva | EK2: ¿El usuario fue valorado en consulta o procedimiento de cuidado paliativo durante este corte? (pueden haber sido múltiples) | EL2: El usuario recibió consulta o procedimiento de cuidado paliativo en este corte, por médico especialista en cuidado paliativo | EM2: El usuario recibió consulta o procedimiento de cuidado paliativo en este corte, por profesional de la salud (no médico, incluye psicólogo) especialista en cuidado paliativo | EN2: El usuario recibió consulta o procedimiento de cuidado paliativo en este corte, por médico especialista, otra especialidad | EO2: El usuario recibió consulta o procedimiento de cuidado paliativo en este corte, por médico general | EP2: El usuario recibió consulta o procedimiento de cuidado paliativo en este corte, por trabajo social | EQ2: El usuario recibió consulta o procedimiento de cuidado paliativo en este corte, por otro profesional de salud (no médico, incluye psicólogo) no especializado | ER2: Fecha de primera consulta o procedimiento de cuidado paliativo en este corte | ES2: Código de la IPS donde recibió la ATENCIÓN de cuidado Paliativo | ET2: ¿Ha sido valorado el usuario por el servicio de psiquiatría durante este corte? | EU2: Fecha de primera consulta con el servicio de psiquiatría (para todos los usuarios) en este corte | EV2: Código de la IPS donde recibió la primera valoración de psiquiatría en este corte | EW2: ¿Fue valorado el usuario por profesional en nutrición durante este corte? | EX2: Fecha de consulta inicial con nutrición en este corte | EY2: Código de la IPS donde recibió la valoración por nutrición, en este corte | EZ2: ¿El usuario recibió soporte nutricional? | FA2: ¿El usuario ha recibido terapias complementarias para su rehabilitación? | FB2: Tipo de tratamiento que está recibiendo el usuario a la fecha de corte | FC2: Resultado final del manejo oncológico en este corte | FD2: Estado vital al finalizar este corte | FE2: Novedad ADMINISTRATIVA del usuario respecto al reporte anterior | FF2: Novedad clínica del usuario a la fecha de corte | FG2: Fecha de desafiliación de la EPS | FH2: Fecha de muerte | FI2: Causa de muerte | FJ2: Código único de identificación BDUA | FK2: Diligencie esta variable con la fecha 2021-01-01
